<?xml version="1.0"?>

<robot xmlns:xacro="http://playerstage.sourceforge.net/gazebo/xmlschema/#xacro">

  <xacro:macro name="rocker" params="name xyz side base_axii tf_prefix=''">

    <link name="${tf_prefix}${name}_rocker_link">
      <inertial>
        <origin xyz="0 0 0" rpy="0 0 0"/>
        <mass value="1.0"/>
        <inertia ixx="0.01" ixy="0" ixz="0" iyy="0.01" iyz="0" izz="0.01"/>
      </inertial>
      <visual>
        <origin xyz="-0.55 ${0.02 * side} -0.04" rpy="0 0 0"/>
        <geometry>
          <mesh filename="package://indomitus_rover_description/meshes/suspension/rocker.stl" scale="0.001 ${0.001 * side} 0.001"/>
        </geometry>
        <material name="steel"/>
      </visual>
      <!-- <collision name="${name}_wheel">
        <origin xyz="0 0 0" rpy="${pi/2} 0 0"/>
        <geometry>
          <cylinder radius="0.05" length="0.042"/>
        </geometry>
        <material name="collision">
          <color rgba="0.8 0.0 0.0 1.0"/>
        </material>
      </collision> -->
    </link>

    <joint name="${tf_prefix}${name}_rocker_joint" type="continuous">
      <origin xyz="${xyz}" rpy="0 0 0"/>
      <parent link="${tf_prefix}${base_axii}"/>
      <child link="${tf_prefix}${name}_rocker_link"/>
      <axis xyz="0 1.0 0"/>
      <limit effort="0" velocity="0"/>
    </joint>

  </xacro:macro>

</robot>
